Workbook

Sheet Batch Enrollment (Metabase)
A1: Batch | B1: Base Batch | C1: GEM Status | D1: Batch Start Date | E1: Initially Enrolled | F1: Currently Enrolled | G1: Refund Requested | H1: Course Cancellation | I1: Deferred | K1: Source: Metabase (Newton School DB). GEM/Non-GEM split from technologies_label ids 728/729. Refreshed: 2026-09-24.
A2: Professional Certificate Course In Data Science - April 2023 | B2: Professional Certificate Course In Data Science - April 2023 | D2: 45025.833 | E2: 72 | F2: 30 | G2: 5 | H2: 25 | I2: 12
A3: Professional Certificate Course In Data Science - May 2023 | B3: Professional Certificate Course In Data Science - May 2023 | D3: 45056.833 | E3: 113 | F3: 51 | G3: 7 | H3: 37 | I3: 18
A4: Professional Certificate Course In Data Science - June 2023 | B4: Professional Certificate Course In Data Science - June 2023 | D4: 45087.833 | E4: 120 | F4: 57 | G4: 5 | H4: 40 | I4: 18
A5: Professional Certificate Course In Data Science - July 2023 | B5: Professional Certificate Course In Data Science - July 2023 | D5: 45119.833 | E5: 119 | F5: 60 | G5: 6 | H5: 38 | I5: 15
A6: Professional Certificate Course In Data Science - July 2023 - August 2023 | B6: Professional Certificate Course In Data Science - July 2023 - August 2023 | D6: 45119.833 | E6: 2 | F6: 0 | G6: 0 | H6: 1 | I6: 1
A7: Professional Certificate Course In Data Science - August 2023 | B7: Professional Certificate Course In Data Science - August 2023 | D7: 45150.833 | E7: 124 | F7: 54 | G7: 13 | H7: 45 | I7: 12
A8: Professional Certificate Course In Data Science - September 2023 | B8: Professional Certificate Course In Data Science - September 2023 | D8: 45176.833 | E8: 113 | F8: 72 | G8: 10 | H8: 27 | I8: 4
A9: Professional Certificate Course In Data Science - October 2023 | B9: Professional Certificate Course In Data Science - October 2023 | D9: 45206.833 | E9: 70 | F9: 43 | G9: 7 | H9: 19 | I9: 1
A10: Professional Certificate Course In Data Science - November 2023 | B10: Professional Certificate Course In Data Science - November 2023 | D10: 45237.833 | E10: 62 | F10: 42 | G10: 5 | H10: 9 | I10: 6
A11: Professional Certificate Course In Data Science - May 2023 - LU | B11: Professional Certificate Course In Data Science - May 2023 - LU | D11: 45261.792 | E11: 65 | F11: 57 | G11: 0 | H11: 8 | I11: 0
A12: Professional Certificate Course In Data Science - December 2023 | B12: Professional Certificate Course In Data Science - December 2023 | D12: 45264 | E12: 69 | F12: 41 | G12: 6 | H12: 13 | I12: 9
A13: Professional Certificate Course In Data Science - January 2024 | B13: Professional Certificate Course In Data Science - January 2024 | D13: 45292 | E13: 84 | F13: 43 | G13: 9 | H13: 28 | I13: 4
... A47: Professional Certificate Course In Data Science October 2026 | B47: Professional Certificate Course In Data Science October 2026 | D47: 46303 | E47: 72 | F47: 72 | G47: 0 | H47: 0 | I47: 0

Sheet Picked Students (raw)
A1: UserID | B1: Batch | C1: Picked Date | D1: GEM Status | E1: Type of Experience | G1: Source: FlyWheel Google Sheet via Sheets API. GEM Status via Metabase label mapping, Type of Experience via col I of 'Prog<>Placement'. Refreshed: 2026-09-24.
A2: 1100600 | B2: Professional Certificate Course In Data Science - May 2023 | C2: 45618
A3: 53455 | B3: Professional Certificate Course In Data Science - April 2023 | C3: 45603
A4: 1095407 | B4: Professional Certificate Course In Data Science - April 2023
A5: 1119799 | B5: Professional Certificate Course In Data Science - April 2023
A6: 1129190 | B6: Professional Certificate Course In Data Science - April 2023 | C6: 45618
A7: 1206721 | B7: Professional Certificate Course In Data Science - April 2023 | C7: 45441
A8: 1243687 | B8: Professional Certificate Course In Data Science - April 2023
A9: 1264264 | B9: Professional Certificate Course In Data Science - April 2023
A10: 16315 | B10: Professional Certificate Course In Data Science - April 2024 | C10: 45594 | E10: Relevant
A11: 109531 | B11: Professional Certificate Course In Data Science - April 2024 | C11: 45594 | E11: Irrelevant (Tech/IT)
A12: 357840 | B12: Professional Certificate Course In Data Science - April 2024 | C12: 45594 | E12: Relevant
A13: 1615732 | B13: Professional Certificate Course In Data Science - April 2024 | C13: 45567 | E13: Relevant
A14: 1680761 | B14: Professional Certificate Course In Data Science - April 2024 | C14: 45594 | E14: Career Gap/ Non Working
A15: 1681619 | B15: Professional Certificate Course In Data Science - April 2024 | C15: 46003 | E15: Relevant
A16: 1682101 | B16: Professional Certificate Course In Data Science - April 2024 | C16: 46008 | E16: Irrelevant (Non Tech) (Grad>2020)
A17: 1683041 | B17: Professional Certificate Course In Data Science - April 2024 | C17: 45714 | E17: Irrelevant (Non Tech) (Grad>2020)
A18: 1684667 | B18: Professional Certificate Course In Data Science - April 2024 | C18: 45603 | E18: Career Gap/ Non Working
A19: 1688286 | B19: Professional Certificate Course In Data Science - April 2024 | C19: 45632 | E19: Career Gap/ Non Working
A20: 1689830 | B20: Professional Certificate Course In Data Science - April 2024 | C20: 45601 | E20: Irrelevant (Grad<2020)
A21: 1135619 | B21: Professional Certificate Course In Data Science - April 2025 | C21: 45911 | E21: Irrelevant (Grad<2020)
... A50: 2269639 | B50: Professional Certificate Course In Data Science - April 2025 | C50: 45968 | E50: Career Gap/ Non Working
A51: 2274979 | B51: Professional Certificate Course In Data Science - April 2025 | C51: 46281
A52: 2283728 | B52: Professional Certificate Course In Data Science - April 2025 | C52: 45937 | E52: Career Gap/ Non Working
A53: 189505 | B53: Professional Certificate Course In Data Science - August 2023 | C53: 45558 | E53: Irrelevant (Tech/IT)
A54: 314155 | B54: Professional Certificate Course In Data Science - August 2023 | C54: 45558 | E54: Relevant
A55: 629353 | B55: Professional Certificate Course In Data Science - August 2023 | C55: 45621 | E55: Irrelevant (Tech/IT)
A56: 1198238 | B56: Professional Certificate Course In Data Science - August 2023 | C56: 45594 | E56: Relevant
A57: 1322203 | B57: Professional Certificate Course In Data Science - August 2023 | C57: 45440
A58: 1330673 | B58: Professional Certificate Course In Data Science - August 2023 | C58: 45819 | E58: Relevant
A59: 1331313 | B59: Professional Certificate Course In Data Science - August 2023 | C59: 45518 | E59: Irrelevant (Non Tech) (Grad>2020)
A60: 1331316 | B60: Professional Certificate Course In Data Science - August 2023 | C60: 45594 | E60: Career Gap/ Non Working
A61: 1348040 | B61: Professional Certificate Course In Data Science - August 2023 | C61: 45601 | E61: Irrelevant (Grad<2020)
A62: 1363893 | B62: Professional Certificate Course In Data Science - August 2023 | C62: 45594 | E62: Career Gap/ Non Working
A63: 1427583 | B63: Professional Certificate Course In Data Science - August 2023 | C63: 45601 | E63: Fresher
A64: 1428159 | B64: Professional Certificate Course In Data Science - August 2023 | C64: 45618
A65: 1432900 | B65: Professional Certificate Course In Data Science - August 2023 | C65: 45627
A66: 1433028 | B66: Professional Certificate Course In Data Science - August 2023 | C66: 45598 | E66: Fresher
A67: 1435856 | B67: Professional Certificate Course In Data Science - August 2023
A68: 1437430 | B68: Professional Certificate Course In Data Science - August 2023 | C68: 45440
...

Sheet Batch Start to Picked date
A1: Batch | B1: Batch (A/B) | C1: Base Batch | D1: GEM Status (raw) | E1: Batch Start Date | F1: Initially Enrolled | G1: Currently Enrolled | H1: Picked Students | I1: Within 30 Days | J1: % of Currently Enrolled | K1: Within 60 Days | L1: % of Currently Enrolled | M1: Within 90 Days | N1: % of Currently Enrolled | O1: Within 120 Days | P1: % of Currently Enrolled | Q1: Within 150 Days | R1: % of Currently Enrolled | S1: Within 180 Days | T1: % of Currently Enrolled | U1: Within 210 Days | V1: % of Currently Enrolled | W1: Within 240 Days | X1: % of Currently Enrolled | Y1: Within 270 Days | Z1: % of Currently Enrolled | AA1: Within 300 Days | AB1: % of Currently Enrolled | AC1: Within 330 Days | AD1: % of Currently Enrolled | AE1: Within 360 Days | AF1: % of Currently Enrolled | AG1: Within 390 Days | AH1: % of Currently Enrolled | AI1: Within 420 Days | AJ1: % of Currently Enrolled | AK1: Within 450 Days | AL1: % of Currently Enrolled | AM1: Within 480 Days | AN1: % of Currently Enrolled | AO1: Within 510 Days | AP1: % of Currently Enrolled | AQ1: Within 540 Days | AR1: % of Currently Enrolled | AS1: Not Placed yet
A2: Professional Certificate Course In Data Science - April 2023 | B2: =IF($A2="","",IFERROR(IF(INDEX('Batch Enrollment (Metabase)'!$C$2:$C$47,MATCH($A2,'Batch Enrollment (Metabase)'!$A$2:$A$47,0))="GEM","A",IF(INDEX('Batch Enrollment (Metabase)'!$C$2:$C$47,MATCH($A2,'Batch Enrollment (Metabase)'!$A$2:$A$47,0))="Non-GEM","B","")),"")) | C2: =IF($A2="","",IFERROR(INDEX('Batch Enrollment (Metabase)'!$B$2:$B$47,MATCH($A2,'Batch Enrollment (Metabase)'!$A$2:$A$47,0)),"")) | D2: =IF($A2="","",IFERROR(INDEX('Batch Enrollment (Metabase)'!$C$2:$C$47,MATCH($A2,'Batch Enrollment (Metabase)'!$A$2:$A$47,0)),"")) | E2: =IF($A2="","",IFERROR(INDEX('Batch Enrollment (Metabase)'!$D$2:$D$47,MATCH($A2,'Batch Enrollment (Metabase)'!$A$2:$A$47,0)),"")) | F2: =IF($A2="","",IFERROR(INDEX('Batch Enrollment (Metabase)'!$E$2:$E$47,MATCH($A2,'Batch Enrollment (Metabase)'!$A$2:$A$47,0)),"")) | G2: =IF($A2="","",IFERROR(INDEX('Batch Enrollment (Metabase)'!$F$2:$F$47,MATCH($A2,'Batch Enrollment (Metabase)'!$A$2:$A$47,0)),"")) | H2: =IF($A2="","",IF($D2="",COUNTIF('Picked Students (raw)'!$B$2:$B$824,$C2),COUNTIFS('Picked Students (raw)'!$B$2:$B$824,$C2,'Picked Students (raw)'!$D$2:$D$824,$D2))) | I2: =IF($A2="","",IF($E2="","",IF(TODAY()<$E2+30,"-",IF($D2="",SUMPRODUCT(('Picked Students (raw)'!$B$2:$B$824=$C2)*('Picked Students (raw)'!$C$2:$C$824<>"")*(('Picked Students (raw)'!$C$2:$C$824-$E2)<30)),SUMPRODUCT(('Picked Students (raw)'!$B$2:$B$824=$C2)*('Picked Students (raw)'!$D$2:$D$824=$D2)*('Picked Students (raw)'!$C$2:$C$824<>"")*(('Picked Students (raw)'!$C$2:$C$824-$E2)<30)))))) | J2: =IF($A2="","",IF(I2="-","-",IF($G2=0,0,I2/$G2))) | K2: =IF($A2="","",IF($E2="","",IF(TODAY()<$E2+60,"-",IF($D2="",SUMPRODUCT(('Picked Students (raw)'!$B$2:$B$824=$C2)*('Picked Students (raw)'!$C$2:$C$824<>"")*(('Picked Students (raw)'!$C$2:$C$824-$E2)<60)),SUMPRODUCT(('Picked Students (raw)'!$B$2:$B$824=$C2)*('Picked Students (raw)'!$D$2:$D$824=$D2)*('Picked Students (raw)'!$C$2:$C$824<>"")*(('Picked Students (raw)'!$C$2:$C$824-$E2)<60)))))) | L2: =IF($A2="","",IF(K2="-","-",IF($G2=0,0,K2/$G2))) | M2: =IF($A2="","",IF($E2="","",IF(TODAY()<$E2+90,"-",IF($D2="",SUMPRODUCT(('Picked Students (raw)'!$B$2:$B$824=$C2)*('Picked Students (raw)'!$C$2:$C$824<>"")*(('Picked Students (raw)'!$C$2:$C$824-$E2)<90)),SUMPRODUCT(('Picked Students (raw)'!$B$2:$B$824=$C2)*('Picked Students (raw)'!$D$2:$D$824=$D2)*('Picked Students (raw)'!$C$2:$C$824<>"")*(('Picked Students (raw)'!$C$2:$C$824-$E2)<90)))))) | N2: =IF($A2="","",IF(M2="-","-",IF($G2=0,0,M2/$G2))) | O2: =IF($A2="","",IF($E2="","",IF(TODAY()<$E2+120,"-",IF($D2="",SUMPRODUCT(('Picked Students (raw)'!$B$2:$B$824=$C2)*('Picked Students (raw)'!$C$2:$C$824<>"")*(('Picked Students (raw)'!$C$2:$C$824-$E2)<120)),SUMPRODUCT(('Picked Students (raw)'!$B$2:$B$824=$C2)*('Picked Students (raw)'!$D$2:$D$824=$D2)*('Picked Students (raw)'!$C$2:$C$824<>"")*(('Picked Students (raw)'!$C$2:$C$824-$E2)<120)))))) | P2: =IF($A2="","",IF(O2="-","-",IF($G2=0,0,O2/$G2))) | Q2: =IF($A2="","",IF($E2="","",IF(TODAY()<$E2+150,"-",IF($D2="",SUMPRODUCT(('Picked Students (raw)'!$B$2:$B$824=$C2)*('Picked Students (raw)'!$C$2:$C$824<>"")*(('Picked Students (raw)'!$C$2:$C$824-$E2)<150)),SUMPRODUCT(('Picked Students (raw)'!$B$2:$B$824=$C2)*('Picked Students (raw)'!$D$2:$D$824=$D2)*('Picked Students (raw)'!$C$2:$C$824<>"")*(('Picked Students (raw)'!$C$2:$C$824-$E2)<150)))))) | R2: =IF($A2="","",IF(Q2="-","-",IF($G2=0,0,Q2/$G2))) | S2: =IF($A2="","",IF($E2="","",IF(TODAY()<$E2+180,"-",IF($D2="",SUMPRODUCT(('Picked Students (raw)'!$B$2:$B$824=$C2)*('Picked Students (raw)'!$C$2:$C$824<>"")*(('Picked Students (raw)'!$C$2:$C$824-$E2)<180)),SUMPRODUCT(('Picked Students (raw)'!$B$2:$B$824=$C2)*('Picked Students (raw)'!$D$2:$D$824=$D2)*('Picked Students (raw)'!$C$2:$C$824<>"")*(('Picked Students (raw)'!$C$2:$C$824-$E2)<180)))))) | T2: =IF($A2="","",IF(S2="-","-",IF($G2=0,0,S2/$G2))) | U2: =IF($A2="","",IF($E2="","",IF(TODAY()<$E2+210,"-",IF($D2="",SUMPRODUCT(('Picked Students (raw)'!$B$2:$B$824=$C2)*('Picked Students (raw)'!$C$2:$C$824<>"")*(('Picked Students (raw)'!$C$2:$C$824-$E2)<210)),SUMPRODUCT(('Picked Students (raw)'!$B$2:$B$824=$C2)*('Picked Students (raw)'!$D$2:$D$824=$D2)*('Picked Students (raw)'!$C$2:$C$824<>"")*(('Picked Students (raw)'!$C$2:$C$824-$E2)<210)))))) | V2: =IF($A2="","",IF(U2="-","-",IF($G2=0,0,U2/$G2))) | W2: =IF($A2="","",IF($E2="","",IF(TODAY()<$E2+240,"-",IF($D2="",SUMPRODUCT(('Picked Students (raw)'!$B$2:$B$824=$C2)*('Picked Students (raw)'!$C$2:$C$824<>"")*(('Picked Students (raw)'!$C$2:$C$824-$E2)<240)),SUMPRODUCT(('Picked Students (raw)'!$B$2:$B$824=$C2)*('Picked Students (raw)'!$D$2:$D$824=$D2)*('Picked Students (raw)'!$C$2:$C$824<>"")*(('Picked Students (raw)'!$C$2:$C$824-$E2)<240)))))) | X2: =IF($A2="","",IF(W2="-","-",IF($G2=0,0,W2/$G2))) | Y2: =IF($A2="","",IF($E2="","",IF(TODAY()<$E2+270,"-",IF($D2="",SUMPRODUCT(('Picked Students (raw)'!$B$2:$B$824=$C2)*('Picked Students (raw)'!$C$2:$C$824<>"")*(('Picked Students (raw)'!$C$2:$C$824-$E2)<270)),SUMPRODUCT(('Picked Students (raw)'!$B$2:$B$824=$C2)*('Picked Students (raw)'!$D$2:$D$824=$D2)*('Picked Students (raw)'!$C$2:$C$824<>"")*(('Picked Students (raw)'!$C$2:$C$824-$E2)<270)))))) | Z2: =IF($A2="","",IF(Y2="-","-",IF($G2=0,0,Y2/$G2))) | AA2: =IF($A2="","",IF($E2="","",IF(TODAY()<$E2+300,"-",IF($D2="",SUMPRODUCT(('Picked Students (raw)'!$B$2:$B$824=$C2)*('Picked Students (raw)'!$C$2:$C$824<>"")*(('Picked Students (raw)'!$C$2:$C$824-$E2)<300)),SUMPRODUCT(('Picked Students (raw)'!$B$2:$B$824=$C2)*('Picked Students (raw)'!$D$2:$D$824=$D2)*('Picked Students (raw)'!$C$2:$C$824<>"")*(('Picked Students (raw)'!$C$2:$C$824-$E2)<300)))))) | AB2: =IF($A2="","",IF(AA2="-","-",IF($G2=0,0,AA2/$G2))) | AC2: =IF($A2="","",IF($E2="","",IF(TODAY()<$E2+330,"-",IF($D2="",SUMPRODUCT(('Picked Students (raw)'!$B$2:$B$824=$C2)*('Picked Students (raw)'!$C$2:$C$824<>"")*(('Picked Students (raw)'!$C$2:$C$824-$E2)<330)),SUMPRODUCT(('Picked Students (raw)'!$B$2:$B$824=$C2)*('Picked Students (raw)'!$D$2:$D$824=$D2)*('Picked Students (raw)'!$C$2:$C$824<>"")*(('Picked Students (raw)'!$C$2:$C$824-$E2)<330)))))) | AD2: =IF($A2="","",IF(AC2="-","-",IF($G2=0,0,AC2/$G2))) | AE2: =IF($A2="","",IF($E2="","",IF(TODAY()<$E2+360,"-",IF($D2="",SUMPRODUCT(('Picked Students (raw)'!$B$2:$B$824=$C2)*('Picked Students (raw)'!$C$2:$C$824<>"")*(('Picked Students (raw)'!$C$2:$C$824-$E2)<360)),SUMPRODUCT(('Picked Students (raw)'!$B$2:$B$824=$C2)*('Picked Students (raw)'!$D$2:$D$824=$D2)*('Picked Students (raw)'!$C$2:$C$824<>"")*(('Picked Students (raw)'!$C$2:$C$824-$E2)<360)))))) | AF2: =IF($A2="","",IF(AE2="-","-",IF($G2=0,0,AE2/$G2))) | AG2: =IF($A2="","",IF($E2="","",IF(TODAY()<$E2+390,"-",IF($D2="",SUMPRODUCT(('Picked Students (raw)'!$B$2:$B$824=$C2)*('Picked Students (raw)'!$C$2:$C$824<>"")*(('Picked Students (raw)'!$C$2:$C$824-$E2)<390)),SUMPRODUCT(('Picked Students (raw)'!$B$2:$B$824=$C2)*('Picked Students (raw)'!$D$2:$D$824=$D2)*('Picked Students (raw)'!$C$2:$C$824<>"")*(('Picked Students (raw)'!$C$2:$C$824-$E2)<390)))))) | AH2: =IF($A2="","",IF(AG2="-","-",IF($G2=0,0,AG2/$G2))) | AI2: =IF($A2="","",IF($E2="","",IF(TODAY()<$E2+420,"-",IF($D2="",SUMPRODUCT(('Picked Students (raw)'!$B$2:$B$824=$C2)*('Picked Students (raw)'!$C$2:$C$824<>"")*(('Picked Students (raw)'!$C$2:$C$824-$E2)<420)),SUMPRODUCT(('Picked Students (raw)'!$B$2:$B$824=$C2)*('Picked Students (raw)'!$D$2:$D$824=$D2)*('Picked Students (raw)'!$C$2:$C$824<>"")*(('Picked Students (raw)'!$C$2:$C$824-$E2)<420)))))) | AJ2: =IF($A2="","",IF(AI2="-","-",IF($G2=0,0,AI2/$G2))) | AK2: =IF($A2="","",IF($E2="","",IF(TODAY()<$E2+450,"-",IF($D2="",SUMPRODUCT(('Picked Students (raw)'!$B$2:$B$824=$C2)*('Picked Students (raw)'!$C$2:$C$824<>"")*(('Picked Students (raw)'!$C$2:$C$824-$E2)<450)),SUMPRODUCT(('Picked Students (raw)'!$B$2:$B$824=$C2)*('Picked Students (raw)'!$D$2:$D$824=$D2)*('Picked Students (raw)'!$C$2:$C$824<>"")*(('Picked Students (raw)'!$C$2:$C$824-$E2)<450)))))) | AL2: =IF($A2="","",IF(AK2="-","-",IF($G2=0,0,AK2/$G2))) | AM2: =IF($A2="","",IF($E2="","",IF(TODAY()<$E2+480,"-",IF($D2="",SUMPRODUCT(('Picked Students (raw)'!$B$2:$B$824=$C2)*('Picked Students (raw)'!$C$2:$C$824<>"")*(('Picked Students (raw)'!$C$2:$C$824-$E2)<480)),SUMPRODUCT(('Picked Students (raw)'!$B$2:$B$824=$C2)*('Picked Students (raw)'!$D$2:$D$824=$D2)*('Picked Students (raw)'!$C$2:$C$824<>"")*(('Picked Students (raw)'!$C$2:$C$824-$E2)<480)))))) | AN2: =IF($A2="","",IF(AM2="-","-",IF($G2=0,0,AM2/$G2))) | AO2: =IF($A2="","",IF($E2="","",IF(TODAY()<$E2+510,"-",IF($D2="",SUMPRODUCT(('Picked Students (raw)'!$B$2:$B$824=$C2)*('Picked Students (raw)'!$C$2:$C$824<>"")*(('Picked Students (raw)'!$C$2:$C$824-$E2)<510)),SUMPRODUCT(('Picked Students (raw)'!$B$2:$B$824=$C2)*('Picked Students (raw)'!$D$2:$D$824=$D2)*('Picked Students (raw)'!$C$2:$C$824<>"")*(('Picked Students (raw)'!$C$2:$C$824-$E2)<510)))))) | AP2: =IF($A2="","",IF(AO2="-","-",IF($G2=0,0,AO2/$G2))) | AQ2: =IF($A2="","",IF($E2="","",IF(TODAY()<$E2+540,"-",IF($D2="",SUMPRODUCT(('Picked Students (raw)'!$B$2:$B$824=$C2)*('Picked Students (raw)'!$C$2:$C$824<>"")*(('Picked Students (raw)'!$C$2:$C$824-$E2)<540)),SUMPRODUCT(('Picked Students (raw)'!$B$2:$B$824=$C2)*('Picked Students (raw)'!$D$2:$D$824=$D2)*('Picked Students (raw)'!$C$2:$C$824<>"")*(('Picked Students (raw)'!$C$2:$C$824-$E2)<540)))))) | AR2: =IF($A2="","",IF(AQ2="-","-",IF($G2=0,0,AQ2/$G2))) | AS2: =IF($A2="","",IF(AQ2="-","-",$H2-AQ2))
A3: Professional Certificate Course In Data Science - May 2023 | B3: =IF($A3="","",IFERROR(IF(INDEX('Batch Enrollment (Metabase)'!$C$2:$C$47,MATCH($A3,'Batch Enrollment (Metabase)'!$A$2:$A$47,0))="GEM","A",IF(INDEX('Batch Enrollment (Metabase)'!$C$2:$C$47,MATCH($A3,'Batch Enrollment (Metabase)'!$A$2:$A$47,0))="Non-GEM","B","")),"")) | C3: =IF($A3="","",IFERROR(INDEX('Batch Enrollment (Metabase)'!$B$2:$B$47,MATCH($A3,'Batch Enrollment (Metabase)'!$A$2:$A$47,0)),"")) | D3: =IF($A3="","",IFERROR(INDEX('Batch Enrollment (Metabase)'!$C$2:$C$47,MATCH($A3,'Batch Enrollment (Metabase)'!$A$2:$A$47,0)),"")) | E3: =IF($A3="","",IFERROR(INDEX('Batch Enrollment (Metabase)'!$D$2:$D$47,MATCH($A3,'Batch Enrollment (Metabase)'!$A$2:$A$47,0)),"")) | F3: =IF($A3="","",IFERROR(INDEX('Batch Enrollment (Metabase)'!$E$2:$E$47,MATCH($A3,'Batch Enrollment (Metabase)'!$A$2:$A$47,0)),"")) | G3: =IF($A3="","",IFERROR(INDEX('Batch Enrollment (Metabase)'!$F$2:$F$47,MATCH($A3,'Batch Enrollment (Metabase)'!$A$2:$A$47,0)),"")) | H3: =IF($A3="","",IF($D3="",COUNTIF('Picked Students (raw)'!$B$2:$B$824,$C3),COUNTIFS('Picked Students (raw)'!$B$2:$B$824,$C3,'Picked Students (raw)'!$D$2:$D$824,$D3))) | I3: =IF($A3="","",IF($E3="","",IF(TODAY()<$E3+30,"-",IF($D3="",SUMPRODUCT(('Picked Students (raw)'!$B$2:$B$824=$C3)*('Picked Students (raw)'!$C$2:$C$824<>"")*(('Picked Students (raw)'!$C$2:$C$824-$E3)<30)),SUMPRODUCT(('Picked Students (raw)'!$B$2:$B$824=$C3)*('Picked Students (raw)'!$D$2:$D$824=$D3)*('Picked Students (raw)'!$C$2:$C$824<>"")*(('Picked Students (raw)'!$C$2:$C$824-$E3)<30)))))) | J3: =IF($A3="","",IF(I3="-","-",IF($G3=0,0,I3/$G3))) | K3: =IF($A3="","",IF($E3="","",IF(TODAY()<$E3+60,"-",IF($D3="",SUMPRODUCT(('Picked Students (raw)'!$B$2:$B$824=$C3)*('Picked Students (raw)'!$C$2:$C$824<>"")*(('Picked Students (raw)'!$C$2:$C$824-$E3)<60)),SUMPRODUCT(('Picked Students (raw)'!$B$2:$B$824=$C3)*('Picked Students (raw)'!$D$2:$D$824=$D3)*('Picked Students (raw)'!$C$2:$C$824<>"")*(('Picked Students (raw)'!$C$2:$C$824-$E3)<60)))))) | L3: =IF($A3="","",IF(K3="-","-",IF($G3=0,0,K3/$G3))) | M3: =IF($A3="","",IF($E3="","",IF(TODAY()<$E3+90,"-",IF($D3="",SUMPRODUCT(('Picked Students (raw)'!$B$2:$B$824=$C3)*('Picked Students (raw)'!$C$2:$C$824<>"")*(('Picked Students (raw)'!$C$2:$C$824-$E3)<90)),SUMPRODUCT(('Picked Students (raw)'!$B$2:$B$824=$C3)*('Picked Students (raw)'!$D$2:$D$824=$D3)*('Picked Students (raw)'!$C$2:$C$824<>"")*(('Picked Students (raw)'!$C$2:$C$824-$E3)<90)))))) | N3: =IF($A3="","",IF(M3="-","-",IF($G3=0,0,M3/$G3))) | O3: =IF($A3="","",IF($E3="","",IF(TODAY()<$E3+120,"-",IF($D3="",SUMPRODUCT(('Picked Students (raw)'!$B$2:$B$824=$C3)*('Picked Students (raw)'!$C$2:$C$824<>"")*(('Picked Students (raw)'!$C$2:$C$824-$E3)<120)),SUMPRODUCT(('Picked Students (raw)'!$B$2:$B$824=$C3)*('Picked Students (raw)'!$D$2:$D$824=$D3)*('Picked Students (raw)'!$C$2:$C$824<>"")*(('Picked Students (raw)'!$C$2:$C$824-$E3)<120)))))) | P3: =IF($A3="","",IF(O3="-","-",IF($G3=0,0,O3/$G3))) | Q3: =IF($A3="","",IF($E3="","",IF(TODAY()<$E3+150,"-",IF($D3="",SUMPRODUCT(('Picked Students (raw)'!$B$2:$B$824=$C3)*('Picked Students (raw)'!$C$2:$C$824<>"")*(('Picked Students (raw)'!$C$2:$C$824-$E3)<150)),SUMPRODUCT(('Picked Students (raw)'!$B$2:$B$824=$C3)*('Picked Students (raw)'!$D$2:$D$824=$D3)*('Picked Students (raw)'!$C$2:$C$824<>"")*(('Picked Students (raw)'!$C$2:$C$824-$E3)<150)))))) | R3: =IF($A3="","",IF(Q3="-","-",IF($G3=0,0,Q3/$G3))) | S3: =IF($A3="","",IF($E3="","",IF(TODAY()<$E3+180,"-",IF($D3="",SUMPRODUCT(('Picked Students (raw)'!$B$2:$B$824=$C3)*('Picked Students (raw)'!$C$2:$C$824<>"")*(('Picked Students (raw)'!$C$2:$C$824-$E3)<180)),SUMPRODUCT(('Picked Students (raw)'!$B$2:$B$824=$C3)*('Picked Students (raw)'!$D$2:$D$824=$D3)*('Picked Students (raw)'!$C$2:$C$824<>"")*(('Picked Students (raw)'!$C$2:$C$824-$E3)<180)))))) | T3: =IF($A3="","",IF(S3="-","-",IF($G3=0,0,S3/$G3))) | U3: =IF($A3="","",IF($E3="","",IF(TODAY()<$E3+210,"-",IF($D3="",SUMPRODUCT(('Picked Students (raw)'!$B$2:$B$824=$C3)*('Picked Students (raw)'!$C$2:$C$824<>"")*(('Picked Students (raw)'!$C$2:$C$824-$E3)<210)),SUMPRODUCT(('Picked Students (raw)'!$B$2:$B$824=$C3)*('Picked Students (raw)'!$D$2:$D$824=$D3)*('Picked Students (raw)'!$C$2:$C$824<>"")*(('Picked Students (raw)'!$C$2:$C$824-$E3)<210)))))) | V3: =IF($A3="","",IF(U3="-","-",IF($G3=0,0,U3/$G3))) | W3: =IF($A3="","",IF($E3="","",IF(TODAY()<$E3+240,"-",IF($D3="",SUMPRODUCT(('Picked Students (raw)'!$B$2:$B$824=$C3)*('Picked Students (raw)'!$C$2:$C$824<>"")*(('Picked Students (raw)'!$C$2:$C$824-$E3)<240)),SUMPRODUCT(('Picked Students (raw)'!$B$2:$B$824=$C3)*('Picked Students (raw)'!$D$2:$D$824=$D3)*('Picked Students (raw)'!$C$2:$C$824<>"")*(('Picked Students (raw)'!$C$2:$C$824-$E3)<240)))))) | X3: =IF($A3="","",IF(W3="-","-",IF($G3=0,0,W3/$G3))) | Y3: =IF($A3="","",IF($E3="","",IF(TODAY()<$E3+270,"-",IF($D3="",SUMPRODUCT(('Picked Students (raw)'!$B$2:$B$824=$C3)*('Picked Students (raw)'!$C$2:$C$824<>"")*(('Picked Students (raw)'!$C$2:$C$824-$E3)<270)),SUMPRODUCT(('Picked Students (raw)'!$B$2:$B$824=$C3)*('Picked Students (raw)'!$D$2:$D$824=$D3)*('Picked Students (raw)'!$C$2:$C$824<>"")*(('Picked Students (raw)'!$C$2:$C$824-$E3)<270)))))) | Z3: =IF($A3="","",IF(Y3="-","-",IF($G3=0,0,Y3/$G3))) | AA3: =IF($A3="","",IF($E3="","",IF(TODAY()<$E3+300,"-",IF($D3="",SUMPRODUCT(('Picked Students (raw)'!$B$2:$B$824=$C3)*('Picked Students (raw)'!$C$2:$C$824<>"")*(('Picked Students (raw)'!$C$2:$C$824-$E3)<300)),SUMPRODUCT(('Picked Students (raw)'!$B$2:$B$824=$C3)*('Picked Students (raw)'!$D$2:$D$824=$D3)*('Picked Students (raw)'!$C$2:$C$824<>"")*(('Picked Students (raw)'!$C$2:$C$824-$E3)<300)))))) | AB3: =IF($A3="","",IF(AA3="-","-",IF($G3=0,0,AA3/$G3))) | AC3: =IF($A3="","",IF($E3="","",IF(TODAY()<$E3+330,"-",IF($D3="",SUMPRODUCT(('Picked Students (raw)'!$B$2:$B$824=$C3)*('Picked Students (raw)'!$C$2:$C$824<>"")*(('Picked Students (raw)'!$C$2:$C$824-$E3)<330)),SUMPRODUCT(('Picked Students (raw)'!$B$2:$B$824=$C3)*('Picked Students (raw)'!$D$2:$D$824=$D3)*('Picked Students (raw)'!$C$2:$C$824<>"")*(('Picked Students (raw)'!$C$2:$C$824-$E3)<330)))))) | AD3: =IF($A3="","",IF(AC3="-","-",IF($G3=0,0,AC3/$G3))) | AE3: =IF($A3="","",IF($E3="","",IF(TODAY()<$E3+360,"-",IF($D3="",SUMPRODUCT(('Picked Students (raw)'!$B$2:$B$824=$C3)*('Picked Students (raw)'!$C$2:$C$824<>"")*(('Picked Students (raw)'!$C$2:$C$824-$E3)<360)),SUMPRODUCT(('Picked Students (raw)'!$B$2:$B$824=$C3)*('Picked Students (raw)'!$D$2:$D$824=$D3)*('Picked Students (raw)'!$C$2:$C$824<>"")*(('Picked Students (raw)'!$C$2:$C$824-$E3)<360)))))) | AF3: =IF($A3="","",IF(AE3="-","-",IF($G3=0,0,AE3/$G3))) | AG3: =IF($A3="","",IF($E3="","",IF(TODAY()<$E3+390,"-",IF($D3="",SUMPRODUCT(('Picked Students (raw)'!$B$2:$B$824=$C3)*('Picked Students (raw)'!$C$2:$C$824<>"")*(('Picked Students (raw)'!$C$2:$C$824-$E3)<390)),SUMPRODUCT(('Picked Students (raw)'!$B$2:$B$824=$C3)*('Picked Students (raw)'!$D$2:$D$824=$D3)*('Picked Students (raw)'!$C$2:$C$824<>"")*(('Picked Students (raw)'!$C$2:$C$824-$E3)<390)))))) | AH3: =IF($A3="","",IF(AG3="-","-",IF($G3=0,0,AG3/$G3))) | AI3: =IF($A3="","",IF($E3="","",IF(TODAY()<$E3+420,"-",IF($D3="",SUMPRODUCT(('Picked Students (raw)'!$B$2:$B$824=$C3)*('Picked Students (raw)'!$C$2:$C$824<>"")*(('Picked Students (raw)'!$C$2:$C$824-$E3)<420)),SUMPRODUCT(('Picked Students (raw)'!$B$2:$B$824=$C3)*('Picked Students (raw)'!$D$2:$D$824=$D3)*('Picked Students (raw)'!$C$2:$C$824<>"")*(('Picked Students (raw)'!$C$2:$C$824-$E3)<420)))))) | AJ3: =IF($A3="","",IF(AI3="-","-",IF($G3=0,0,AI3/$G3))) | AK3: =IF($A3="","",IF($E3="","",IF(TODAY()<$E3+450,"-",IF($D3="",SUMPRODUCT(('Picked Students (raw)'!$B$2:$B$824=$C3)*('Picked Students (raw)'!$C$2:$C$824<>"")*(('Picked Students (raw)'!$C$2:$C$824-$E3)<450)),SUMPRODUCT(('Picked Students (raw)'!$B$2:$B$824=$C3)*('Picked Students (raw)'!$D$2:$D$824=$D3)*('Picked Students (raw)'!$C$2:$C$824<>"")*(('Picked Students (raw)'!$C$2:$C$824-$E3)<450)))))) | AL3: =IF($A3="","",IF(AK3="-","-",IF($G3=0,0,AK3/$G3))) | AM3: =IF($A3="","",IF($E3="","",IF(TODAY()<$E3+480,"-",IF($D3="",SUMPRODUCT(('Picked Students (raw)'!$B$2:$B$824=$C3)*('Picked Students (raw)'!$C$2:$C$824<>"")*(('Picked Students (raw)'!$C$2:$C$824-$E3)<480)),SUMPRODUCT(('Picked Students (raw)'!$B$2:$B$824=$C3)*('Picked Students (raw)'!$D$2:$D$824=$D3)*('Picked Students (raw)'!$C$2:$C$824<>"")*(('Picked Students (raw)'!$C$2:$C$824-$E3)<480)))))) | AN3: =IF($A3="","",IF(AM3="-","-",IF($G3=0,0,AM3/$G3))) | AO3: =IF($A3="","",IF($E3="","",IF(TODAY()<$E3+510,"-",IF($D3="",SUMPRODUCT(('Picked Students (raw)'!$B$2:$B$824=$C3)*('Picked Students (raw)'!$C$2:$C$824<>"")*(('Picked Students (raw)'!$C$2:$C$824-$E3)<510)),SUMPRODUCT(('Picked Students (raw)'!$B$2:$B$824=$C3)*('Picked Students (raw)'!$D$2:$D$824=$D3)*('Picked Students (raw)'!$C$2:$C$824<>"")*(('Picked Students (raw)'!$C$2:$C$824-$E3)<510)))))) | AP3: =IF($A3="","",IF(AO3="-","-",IF($G3=0,0,AO3/$G3))) | AQ3: =IF($A3="","",IF($E3="","",IF(TODAY()<$E3+540,"-",IF($D3="",SUMPRODUCT(('Picked Students (raw)'!$B$2:$B$824=$C3)*('Picked Students (raw)'!$C$2:$C$824<>"")*(('Picked Students (raw)'!$C$2:$C$824-$E3)<540)),SUMPRODUCT(('Picked Students (raw)'!$B$2:$B$824=$C3)*('Picked Students (raw)'!$D$2:$D$824=$D3)*('Picked Students (raw)'!$C$2:$C$824<>"")*(('Picked Students (raw)'!$C$2:$C$824-$E3)<540)))))) | AR3: =IF($A3="","",IF(AQ3="-","-",IF($G3=0,0,AQ3/$G3))) | AS3: =IF($A3="","",IF(AQ3="-","-",$H3-AQ3))
A4: Professional Certificate Course In Data Science - June 2023 | B4: =IF($A4="","",IFERROR(IF(INDEX('Batch Enrollment (Metabase)'!$C$2:$C$47,MATCH($A4,'Batch Enrollment (Metabase)'!$A$2:$A$47,0))="GEM","A",IF(INDEX('Batch Enrollment (Metabase)'!$C$2:$C$47,MATCH($A4,'Batch Enrollment (Metabase)'!$A$2:$A$47,0))="Non-GEM","B","")),"")) | C4: =IF($A4="","",IFERROR(INDEX('Batch Enrollment (Metabase)'!$B$2:$B$47,MATCH($A4,'Batch Enrollment (Metabase)'!$A$2:$A$47,0)),"")) | D4: =IF($A4="","",IFERROR(INDEX('Batch Enrollment (Metabase)'!$C$2:$C$47,MATCH($A4,'Batch Enrollment (Metabase)'!$A$2:$A$47,0)),"")) | E4: =IF($A4="","",IFERROR(INDEX('Batch Enrollment (Metabase)'!$D$2:$D$47,MATCH($A4,'Batch Enrollment (Metabase)'!$A$2:$A$47,0)),"")) | F4: =IF($A4="","",IFERROR(INDEX('Batch Enrollment (Metabase)'!$E$2:$E$47,MATCH($A4,'Batch Enrollment (Metabase)'!$A$2:$A$47,0)),"")) | G4: =IF($A4="","",IFERROR(INDEX('Batch Enrollment (Metabase)'!$F$2:$F$47,MATCH($A4,'Batch Enrollment (Metabase)'!$A$2:$A$47,0)),"")) | H4: =IF($A4="","",IF($D4="",COUNTIF('Picked Students (raw)'!$B$2:$B$824,$C4),COUNTIFS('Picked Students (raw)'!$B$2:$B$824,$C4,'Picked Students (raw)'!$D$2:$D$824,$D4))) | I4: =IF($A4="","",IF($E4="","",IF(TODAY()<$E4+30,"-",IF($D4="",SUMPRODUCT(('Picked Students (raw)'!$B$2:$B$824=$C4)*('Picked Students (raw)'!$C$2:$C$824<>"")*(('Picked Students (raw)'!$C$2:$C$824-$E4)<30)),SUMPRODUCT(('Picked Students (raw)'!$B$2:$B$824=$C4)*('Picked Students (raw)'!$D$2:$D$824=$D4)*('Picked Students (raw)'!$C$2:$C$824<>"")*(('Picked Students (raw)'!$C$2:$C$824-$E4)<30)))))) | J4: =IF($A4="","",IF(I4="-","-",IF($G4=0,0,I4/$G4))) | K4: =IF($A4="","",IF($E4="","",IF(TODAY()<$E4+60,"-",IF($D4="",SUMPRODUCT(('Picked Students (raw)'!$B$2:$B$824=$C4)*('Picked Students (raw)'!$C$2:$C$824<>"")*(('Picked Students (raw)'!$C$2:$C$824-$E4)<60)),SUMPRODUCT(('Picked Students (raw)'!$B$2:$B$824=$C4)*('Picked Students (raw)'!$D$2:$D$824=$D4)*('Picked Students (raw)'!$C$2:$C$824<>"")*(('Picked Students (raw)'!$C$2:$C$824-$E4)<60)))))) | L4: =IF($A4="","",IF(K4="-","-",IF($G4=0,0,K4/$G4))) | M4: =IF($A4="","",IF($E4="","",IF(TODAY()<$E4+90,"-",IF($D4="",SUMPRODUCT(('Picked Students (raw)'!$B$2:$B$824=$C4)*('Picked Students (raw)'!$C$2:$C$824<>"")*(('Picked Students (raw)'!$C$2:$C$824-$E4)<90)),SUMPRODUCT(('Picked Students (raw)'!$B$2:$B$824=$C4)*('Picked Students (raw)'!$D$2:$D$824=$D4)*('Picked Students (raw)'!$C$2:$C$824<>"")*(('Picked Students (raw)'!$C$2:$C$824-$E4)<90)))))) | N4: =IF($A4="","",IF(M4="-","-",IF($G4=0,0,M4/$G4))) | O4: =IF($A4="","",IF($E4="","",IF(TODAY()<$E4+120,"-",IF($D4="",SUMPRODUCT(('Picked Students (raw)'!$B$2:$B$824=$C4)*('Picked Students (raw)'!$C$2:$C$824<>"")*(('Picked Students (raw)'!$C$2:$C$824-$E4)<120)),SUMPRODUCT(('Picked Students (raw)'!$B$2:$B$824=$C4)*('Picked Students (raw)'!$D$2:$D$824=$D4)*('Picked Students (raw)'!$C$2:$C$824<>"")*(('Picked Students (raw)'!$C$2:$C$824-$E4)<120)))))) | P4: =IF($A4="","",IF(O4="-","-",IF($G4=0,0,O4/$G4))) | Q4: =IF($A4="","",IF($E4="","",IF(TODAY()<$E4+150,"-",IF($D4="",SUMPRODUCT(('Picked Students (raw)'!$B$2:$B$824=$C4)*('Picked Students (raw)'!$C$2:$C$824<>"")*(('Picked Students (raw)'!$C$2:$C$824-$E4)<150)),SUMPRODUCT(('Picked Students (raw)'!$B$2:$B$824=$C4)*('Picked Students (raw)'!$D$2:$D$824=$D4)*('Picked Students (raw)'!$C$2:$C$824<>"")*(('Picked Students (raw)'!$C$2:$C$824-$E4)<150)))))) | R4: =IF($A4="","",IF(Q4="-","-",IF($G4=0,0,Q4/$G4))) | S4: =IF($A4="","",IF($E4="","",IF(TODAY()<$E4+180,"-",IF($D4="",SUMPRODUCT(('Picked Students (raw)'!$B$2:$B$824=$C4)*('Picked Students (raw)'!$C$2:$C$824<>"")*(('Picked Students (raw)'!$C$2:$C$824-$E4)<180)),SUMPRODUCT(('Picked Students (raw)'!$B$2:$B$824=$C4)*('Picked Students (raw)'!$D$2:$D$824=$D4)*('Picked Students (raw)'!$C$2:$C$824<>"")*(('Picked Students (raw)'!$C$2:$C$824-$E4)<180)))))) | T4: =IF($A4="","",IF(S4="-","-",IF($G4=0,0,S4/$G4))) | U4: =IF($A4="","",IF($E4="","",IF(TODAY()<$E4+210,"-",IF($D4="",SUMPRODUCT(('Picked Students (raw)'!$B$2:$B$824=$C4)*('Picked Students (raw)'!$C$2:$C$824<>"")*(('Picked Students (raw)'!$C$2:$C$824-$E4)<210)),SUMPRODUCT(('Picked Students (raw)'!$B$2:$B$824=$C4)*('Picked Students (raw)'!$D$2:$D$824=$D4)*('Picked Students (raw)'!$C$2:$C$824<>"")*(('Picked Students (raw)'!$C$2:$C$824-$E4)<210)))))) | V4: =IF($A4="","",IF(U4="-","-",IF($G4=0,0,U4/$G4))) | W4: =IF($A4="","",IF($E4="","",IF(TODAY()<$E4+240,"-",IF($D4="",SUMPRODUCT(('Picked Students (raw)'!$B$2:$B$824=$C4)*('Picked Students (raw)'!$C$2:$C$824<>"")*(('Picked Students (raw)'!$C$2:$C$824-$E4)<240)),SUMPRODUCT(('Picked Students (raw)'!$B$2:$B$824=$C4)*('Picked Students (raw)'!$D$2:$D$824=$D4)*('Picked Students (raw)'!$C$2:$C$824<>"")*(('Picked Students (raw)'!$C$2:$C$824-$E4)<240)))))) | X4: =IF($A4="","",IF(W4="-","-",IF($G4=0,0,W4/$G4))) | Y4: =IF($A4="","",IF($E4="","",IF(TODAY()<$E4+270,"-",IF($D4="",SUMPRODUCT(('Picked Students (raw)'!$B$2:$B$824=$C4)*('Picked Students (raw)'!$C$2:$C$824<>"")*(('Picked Students (raw)'!$C$2:$C$824-$E4)<270)),SUMPRODUCT(('Picked Students (raw)'!$B$2:$B$824=$C4)*('Picked Students (raw)'!$D$2:$D$824=$D4)*('Picked Students (raw)'!$C$2:$C$824<>"")*(('Picked Students (raw)'!$C$2:$C$824-$E4)<270)))))) | Z4: =IF($A4="","",IF(Y4="-","-",IF($G4=0,0,Y4/$G4))) | AA4: =IF($A4="","",IF($E4="","",IF(TODAY()<$E4+300,"-",IF($D4="",SUMPRODUCT(('Picked Students (raw)'!$B$2:$B$824=$C4)*('Picked Students (raw)'!$C$2:$C$824<>"")*(('Picked Students (raw)'!$C$2:$C$824-$E4)<300)),SUMPRODUCT(('Picked Students (raw)'!$B$2:$B$824=$C4)*('Picked Students (raw)'!$D$2:$D$824=$D4)*('Picked Students (raw)'!$C$2:$C$824<>"")*(('Picked Students (raw)'!$C$2:$C$824-$E4)<300)))))) | AB4: =IF($A4="","",IF(AA4="-","-",IF($G4=0,0,AA4/$G4))) | AC4: =IF($A4="","",IF($E4="","",IF(TODAY()<$E4+330,"-",IF($D4="",SUMPRODUCT(('Picked Students (raw)'!$B$2:$B$824=$C4)*('Picked Students (raw)'!$C$2:$C$824<>"")*(('Picked Students (raw)'!$C$2:$C$824-$E4)<330)),SUMPRODUCT(('Picked Students (raw)'!$B$2:$B$824=$C4)*('Picked Students (raw)'!$D$2:$D$824=$D4)*('Picked Students (raw)'!$C$2:$C$824<>"")*(('Picked Students (raw)'!$C$2:$C$824-$E4)<330)))))) | AD4: =IF($A4="","",IF(AC4="-","-",IF($G4=0,0,AC4/$G4))) | AE4: =IF($A4="","",IF($E4="","",IF(TODAY()<$E4+360,"-",IF($D4="",SUMPRODUCT(('Picked Students (raw)'!$B$2:$B$824=$C4)*('Picked Students (raw)'!$C$2:$C$824<>"")*(('Picked Students (raw)'!$C$2:$C$824-$E4)<360)),SUMPRODUCT(('Picked Students (raw)'!$B$2:$B$824=$C4)*('Picked Students (raw)'!$D$2:$D$824=$D4)*('Picked Students (raw)'!$C$2:$C$824<>"")*(('Picked Students (raw)'!$C$2:$C$824-$E4)<360)))))) | AF4: =IF($A4="","",IF(AE4="-","-",IF($G4=0,0,AE4/$G4))) | AG4: =IF($A4="","",IF($E4="","",IF(TODAY()<$E4+390,"-",IF($D4="",SUMPRODUCT(('Picked Students (raw)'!$B$2:$B$824=$C4)*('Picked Students (raw)'!$C$2:$C$824<>"")*(('Picked Students (raw)'!$C$2:$C$824-$E4)<390)),SUMPRODUCT(('Picked Students (raw)'!$B$2:$B$824=$C4)*('Picked Students (raw)'!$D$2:$D$824=$D4)*('Picked Students (raw)'!$C$2:$C$824<>"")*(('Picked Students (raw)'!$C$2:$C$824-$E4)<390)))))) | AH4: =IF($A4="","",IF(AG4="-","-",IF($G4=0,0,AG4/$G4))) | AI4: =IF($A4="","",IF($E4="","",IF(TODAY()<$E4+420,"-",IF($D4="",SUMPRODUCT(('Picked Students (raw)'!$B$2:$B$824=$C4)*('Picked Students (raw)'!$C$2:$C$824<>"")*(('Picked Students (raw)'!$C$2:$C$824-$E4)<420)),SUMPRODUCT(('Picked Students (raw)'!$B$2:$B$824=$C4)*('Picked Students (raw)'!$D$2:$D$824=$D4)*('Picked Students (raw)'!$C$2:$C$824<>"")*(('Picked Students (raw)'!$C$2:$C$824-$E4)<420)))))) | AJ4: =IF($A4="","",IF(AI4="-","-",IF($G4=0,0,AI4/$G4))) | AK4: =IF($A4="","",IF($E4="","",IF(TODAY()<$E4+450,"-",IF($D4="",SUMPRODUCT(('Picked Students (raw)'!$B$2:$B$824=$C4)*('Picked Students (raw)'!$C$2:$C$824<>"")*(('Picked Students (raw)'!$C$2:$C$824-$E4)<450)),SUMPRODUCT(('Picked Students (raw)'!$B$2:$B$824=$C4)*('Picked Students (raw)'!$D$2:$D$824=$D4)*('Picked Students (raw)'!$C$2:$C$824<>"")*(('Picked Students (raw)'!$C$2:$C$824-$E4)<450)))))) | AL4: =IF($A4="","",IF(AK4="-","-",IF($G4=0,0,AK4/$G4))) | AM4: =IF($A4="","",IF($E4="","",IF(TODAY()<$E4+480,"-",IF($D4="",SUMPRODUCT(('Picked Students (raw)'!$B$2:$B$824=$C4)*('Picked Students (raw)'!$C$2:$C$824<>"")*(('Picked Students (raw)'!$C$2:$C$824-$E4)<480)),SUMPRODUCT(('Picked Students (raw)'!$B$2:$B$824=$C4)*('Picked Students (raw)'!$D$2:$D$824=$D4)*('Picked Students (raw)'!$C$2:$C$824<>"")*(('Picked Students (raw)'!$C$2:$C$824-$E4)<480)))))) | AN4: =IF($A4="","",IF(AM4="-","-",IF($G4=0,0,AM4/$G4))) | AO4: =IF($A4="","",IF($E4="","",IF(TODAY()<$E4+510,"-",IF($D4="",SUMPRODUCT(('Picked Students (raw)'!$B$2:$B$824=$C4)*('Picked Students (raw)'!$C$2:$C$824<>"")*(('Picked Students (raw)'!$C$2:$C$824-$E4)<510)),SUMPRODUCT(('Picked Students (raw)'!$B$2:$B$824=$C4)*('Picked Students (raw)'!$D$2:$D$824=$D4)*('Picked Students (raw)'!$C$2:$C$824<>"")*(('Picked Students (raw)'!$C$2:$C$824-$E4)<510)))))) | AP4: =IF($A4="","",IF(AO4="-","-",IF($G4=0,0,AO4/$G4))) | AQ4: =IF($A4="","",IF($E4="","",IF(TODAY()<$E4+540,"-",IF($D4="",SUMPRODUCT(('Picked Students (raw)'!$B$2:$B$824=$C4)*('Picked Students (raw)'!$C$2:$C$824<>"")*(('Picked Students (raw)'!$C$2:$C$824-$E4)<540)),SUMPRODUCT(('Picked Students (raw)'!$B$2:$B$824=$C4)*('Picked Students (raw)'!$D$2:$D$824=$D4)*('Picked Students (raw)'!$C$2:$C$824<>"")*(('Picked Students (raw)'!$C$2:$C$824-$E4)<540)))))) | AR4: =IF($A4="","",IF(AQ4="-","-",IF($G4=0,0,AQ4/$G4))) | AS4: =IF($A4="","",IF(AQ4="-","-",$H4-AQ4))
A5: Professional Certificate Course In Data Science - July 2023 | B5: =IF($A5="","",IFERROR(IF(INDEX('Batch Enrollment (Metabase)'!$C$2:$C$47,MATCH($A5,'Batch Enrollment (Metabase)'!$A$2:$A$47,0))="GEM","A",IF(INDEX('Batch Enrollment (Metabase)'!$C$2:$C$47,MATCH($A5,'Batch Enrollment (Metabase)'!$A$2:$A$47,0))="Non-GEM","B","")),"")) | C5: =IF($A5="","",IFERROR(INDEX('Batch Enrollment (Metabase)'!$B$2:$B$47,MATCH($A5,'Batch Enrollment (Metabase)'!$A$2:$A$47,0)),"")) | D5: =IF($A5="","",IFERROR(INDEX('Batch Enrollment (Metabase)'!$C$2:$C$47,MATCH($A5,'Batch Enrollment (Metabase)'!$A$2:$A$47,0)),"")) | E5: =IF($A5="","",IFERROR(INDEX('Batch Enrollment (Metabase)'!$D$2:$D$47,MATCH($A5,'Batch Enrollment (Metabase)'!$A$2:$A$47,0)),"")) | F5: =IF($A5="","",IFERROR(INDEX('Batch Enrollment (Metabase)'!$E$2:$E$47,MATCH($A5,'Batch Enrollment (Metabase)'!$A$2:$A$47,0)),"")) | G5: =IF($A5="","",IFERROR(INDEX('Batch Enrollment (Metabase)'!$F$2:$F$47,MATCH($A5,'Batch Enrollment (Metabase)'!$A$2:$A$47,0)),"")) | H5: =IF($A5="","",IF($D5="",COUNTIF('Picked Students (raw)'!$B$2:$B$824,$C5),COUNTIFS('Picked Students (raw)'!$B$2:$B$824,$C5,'Picked Students (raw)'!$D$2:$D$824,$D5))) | I5: =IF($A5="","",IF($E5="","",IF(TODAY()<$E5+30,"-",IF($D5="",SUMPRODUCT(('Picked Students (raw)'!$B$2:$B$824=$C5)*('Picked Students (raw)'!$C$2:$C$824<>"")*(('Picked Students (raw)'!$C$2:$C$824-$E5)<30)),SUMPRODUCT(('Picked Students (raw)'!$B$2:$B$824=$C5)*('Picked Students (raw)'!$D$2:$D$824=$D5)*('Picked Students (raw)'!$C$2:$C$824<>"")*(('Picked Students (raw)'!$C$2:$C$824-$E5)<30)))))) | J5: =IF($A5="","",IF(I5="-","-",IF($G5=0,0,I5/$G5))) | K5: =IF($A5="","",IF($E5="","",IF(TODAY()<$E5+60,"-",IF($D5="",SUMPRODUCT(('Picked Students (raw)'!$B$2:$B$824=$C5)*('Picked Students (raw)'!$C$2:$C$824<>"")*(('Picked Students (raw)'!$C$2:$C$824-$E5)<60)),SUMPRODUCT(('Picked Students (raw)'!$B$2:$B$824=$C5)*('Picked Students (raw)'!$D$2:$D$824=$D5)*('Picked Students (raw)'!$C$2:$C$824<>"")*(('Picked Students (raw)'!$C$2:$C$824-$E5)<60)))))) | L5: =IF($A5="","",IF(K5="-","-",IF($G5=0,0,K5/$G5))) | M5: =IF($A5="","",IF($E5="","",IF(TODAY()<$E5+90,"-",IF($D5="",SUMPRODUCT(('Picked Students (raw)'!$B$2:$B$824=$C5)*('Picked Students (raw)'!$C$2:$C$824<>"")*(('Picked Students (raw)'!$C$2:$C$824-$E5)<90)),SUMPRODUCT(('Picked Students (raw)'!$B$2:$B$824=$C5)*('Picked Students (raw)'!$D$2:$D$824=$D5)*('Picked Students (raw)'!$C$2:$C$824<>"")*(('Picked Students (raw)'!$C$2:$C$824-$E5)<90)))))) | N5: =IF($A5="","",IF(M5="-","-",IF($G5=0,0,M5/$G5))) | O5: =IF($A5="","",IF($E5="","",IF(TODAY()<$E5+120,"-",IF($D5="",SUMPRODUCT(('Picked Students (raw)'!$B$2:$B$824=$C5)*('Picked Students (raw)'!$C$2:$C$824<>"")*(('Picked Students (raw)'!$C$2:$C$824-$E5)<120)),SUMPRODUCT(('Picked Students (raw)'!$B$2:$B$824=$C5)*('Picked Students (raw)'!$D$2:$D$824=$D5)*('Picked Students (raw)'!$C$2:$C$824<>"")*(('Picked Students (raw)'!$C$2:$C$824-$E5)<120)))))) | P5: =IF($A5="","",IF(O5="-","-",IF($G5=0,0,O5/$G5))) | Q5: =IF($A5="","",IF($E5="","",IF(TODAY()<$E5+150,"-",IF($D5="",SUMPRODUCT(('Picked Students (raw)'!$B$2:$B$824=$C5)*('Picked Students (raw)'!$C$2:$C$824<>"")*(('Picked Students (raw)'!$C$2:$C$824-$E5)<150)),SUMPRODUCT(('Picked Students (raw)'!$B$2:$B$824=$C5)*('Picked Students (raw)'!$D$2:$D$824=$D5)*('Picked Students (raw)'!$C$2:$C$824<>"")*(('Picked Students (raw)'!$C$2:$C$824-$E5)<150)))))) | R5: =IF($A5="","",IF(Q5="-","-",IF($G5=0,0,Q5/$G5))) | S5: =IF($A5="","",IF($E5="","",IF(TODAY()<$E5+180,"-",IF($D5="",SUMPRODUCT(('Picked Students (raw)'!$B$2:$B$824=$C5)*('Picked Students (raw)'!$C$2:$C$824<>"")*(('Picked Students (raw)'!$C$2:$C$824-$E5)<180)),SUMPRODUCT(('Picked Students (raw)'!$B$2:$B$824=$C5)*('Picked Students (raw)'!$D$2:$D$824=$D5)*('Picked Students (raw)'!$C$2:$C$824<>"")*(('Picked Students (raw)'!$C$2:$C$824-$E5)<180)))))) | T5: =IF($A5="","",IF(S5="-","-",IF($G5=0,0,S5/$G5))) | U5: =IF($A5="","",IF($E5="","",IF(TODAY()<$E5+210,"-",IF($D5="",SUMPRODUCT(('Picked Students (raw)'!$B$2:$B$824=$C5)*('Picked Students (raw)'!$C$2:$C$824<>"")*(('Picked Students (raw)'!$C$2:$C$824-$E5)<210)),SUMPRODUCT(('Picked Students (raw)'!$B$2:$B$824=$C5)*('Picked Students (raw)'!$D$2:$D$824=$D5)*('Picked Students (raw)'!$C$2:$C$824<>"")*(('Picked Students (raw)'!$C$2:$C$824-$E5)<210)))))) | V5: =IF($A5="","",IF(U5="-","-",IF($G5=0,0,U5/$G5))) | W5: =IF($A5="","",IF($E5="","",IF(TODAY()<$E5+240,"-",IF($D5="",SUMPRODUCT(('Picked Students (raw)'!$B$2:$B$824=$C5)*('Picked Students (raw)'!$C$2:$C$824<>"")*(('Picked Students (raw)'!$C$2:$C$824-$E5)<240)),SUMPRODUCT(('Picked Students (raw)'!$B$2:$B$824=$C5)*('Picked Students (raw)'!$D$2:$D$824=$D5)*('Picked Students (raw)'!$C$2:$C$824<>"")*(('Picked Students (raw)'!$C$2:$C$824-$E5)<240)))))) | X5: =IF($A5="","",IF(W5="-","-",IF($G5=0,0,W5/$G5))) | Y5: =IF($A5="","",IF($E5="","",IF(TODAY()<$E5+270,"-",IF($D5="",SUMPRODUCT(('Picked Students (raw)'!$B$2:$B$824=$C5)*('Picked Students (raw)'!$C$2:$C$824<>"")*(('Picked Students (raw)'!$C$2:$C$824-$E5)<270)),SUMPRODUCT(('Picked Students (raw)'!$B$2:$B$824=$C5)*('Picked Students (raw)'!$D$2:$D$824=$D5)*('Picked Students (raw)'!$C$2:$C$824<>"")*(('Picked Students (raw)'!$C$2:$C$824-$E5)<270)))))) | Z5: =IF($A5="","",IF(Y5="-","-",IF($G5=0,0,Y5/$G5))) | AA5: =IF($A5="","",IF($E5="","",IF(TODAY()<$E5+300,"-",IF($D5="",SUMPRODUCT(('Picked Students (raw)'!$B$2:$B$824=$C5)*('Picked Students (raw)'!$C$2:$C$824<>"")*(('Picked Students (raw)'!$C$2:$C$824-$E5)<300)),SUMPRODUCT(('Picked Students (raw)'!$B$2:$B$824=$C5)*('Picked Students (raw)'!$D$2:$D$824=$D5)*('Picked Students (raw)'!$C$2:$C$824<>"")*(('Picked Students (raw)'!$C$2:$C$824-$E5)<300)))))) | AB5: =IF($A5="","",IF(AA5="-","-",IF($G5=0,0,AA5/$G5))) | AC5: =IF($A5="","",IF($E5="","",IF(TODAY()<$E5+330,"-",IF($D5="",SUMPRODUCT(('Picked Students (raw)'!$B$2:$B$824=$C5)*('Picked Students (raw)'!$C$2:$C$824<>"")*(('Picked Students (raw)'!$C$2:$C$824-$E5)<330)),SUMPRODUCT(('Picked Students (raw)'!$B$2:$B$824=$C5)*('Picked Students (raw)'!$D$2:$D$824=$D5)*('Picked Students (raw)'!$C$2:$C$824<>"")*(('Picked Students (raw)'!$C$2:$C$824-$E5)<330)))))) | AD5: =IF($A5="","",IF(AC5="-","-",IF($G5=0,0,AC5/$G5))) | AE5: =IF($A5="","",IF($E5="","",IF(TODAY()<$E5+360,"-",IF($D5="",SUMPRODUCT(('Picked Students (raw)'!$B$2:$B$824=$C5)*('Picked Students (raw)'!$C$2:$C$824<>"")*(('Picked Students (raw)'!$C$2:$C$824-$E5)<360)),SUMPRODUCT(('Picked Students (raw)'!$B$2:$B$824=$C5)*('Picked Students (raw)'!$D$2:$D$824=$D5)*('Picked Students (raw)'!$C$2:$C$824<>"")*(('Picked Students (raw)'!$C$2:$C$824-$E5)<360)))))) | AF5: =IF($A5="","",IF(AE5="-","-",IF($G5=0,0,AE5/$G5))) | AG5: =IF($A5="","",IF($E5="","",IF(TODAY()<$E5+390,"-",IF($D5="",SUMPRODUCT(('Picked Students (raw)'!$B$2:$B$824=$C5)*('Picked Students (raw)'!$C$2:$C$824<>"")*(('Picked Students (raw)'!$C$2:$C$824-$E5)<390)),SUMPRODUCT(('Picked Students (raw)'!$B$2:$B$824=$C5)*('Picked Students (raw)'!$D$2:$D$824=$D5)*('Picked Students (raw)'!$C$2:$C$824<>"")*(('Picked Students (raw)'!$C$2:$C$824-$E5)<390)))))) | AH5: =IF($A5="","",IF(AG5="-","-",IF($G5=0,0,AG5/$G5))) | AI5: =IF($A5="","",IF($E5="","",IF(TODAY()<$E5+420,"-",IF($D5="",SUMPRODUCT(('Picked Students (raw)'!$B$2:$B$824=$C5)*('Picked Students (raw)'!$C$2:$C$824<>"")*(('Picked Students (raw)'!$C$2:$C$824-$E5)<420)),SUMPRODUCT(('Picked Students (raw)'!$B$2:$B$824=$C5)*('Picked Students (raw)'!$D$2:$D$824=$D5)*('Picked Students (raw)'!$C$2:$C$824<>"")*(('Picked Students (raw)'!$C$2:$C$824-$E5)<420)))))) | AJ5: =IF($A5="","",IF(AI5="-","-",IF($G5=0,0,AI5/$G5))) | AK5: =IF($A5="","",IF($E5="","",IF(TODAY()<$E5+450,"-",IF($D5="",SUMPRODUCT(('Picked Students (raw)'!$B$2:$B$824=$C5)*('Picked Students (raw)'!$C$2:$C$824<>"")*(('Picked Students (raw)'!$C$2:$C$824-$E5)<450)),SUMPRODUCT(('Picked Students (raw)'!$B$2:$B$824=$C5)*('Picked Students (raw)'!$D$2:$D$824=$D5)*('Picked Students (raw)'!$C$2:$C$824<>"")*(('Picked Students (raw)'!$C$2:$C$824-$E5)<450)))))) | AL5: =IF($A5="","",IF(AK5="-","-",IF($G5=0,0,AK5/$G5))) | AM5: =IF($A5="","",IF($E5="","",IF(TODAY()<$E5+480,"-",IF($D5="",SUMPRODUCT(('Picked Students (raw)'!$B$2:$B$824=$C5)*('Picked Students (raw)'!$C$2:$C$824<>"")*(('Picked Students (raw)'!$C$2:$C$824-$E5)<480)),SUMPRODUCT(('Picked Students (raw)'!$B$2:$B$824=$C5)*('Picked Students (raw)'!$D$2:$D$824=$D5)*('Picked Students (raw)'!$C$2:$C$824<>"")*(('Picked Students (raw)'!$C$2:$C$824-$E5)<480)))))) | AN5: =IF($A5="","",IF(AM5="-","-",IF($G5=0,0,AM5/$G5))) | AO5: =IF($A5="","",IF($E5="","",IF(TODAY()<$E5+510,"-",IF($D5="",SUMPRODUCT(('Picked Students (raw)'!$B$2:$B$824=$C5)*('Picked Students (raw)'!$C$2:$C$824<>"")*(('Picked Students (raw)'!$C$2:$C$824-$E5)<510)),SUMPRODUCT(('Picked Students (raw)'!$B$2:$B$824=$C5)*('Picked Students (raw)'!$D$2:$D$824=$D5)*('Picked Students (raw)'!$C$2:$C$824<>"")*(('Picked Students (raw)'!$C$2:$C$824-$E5)<510)))))) | AP5: =IF($A5="","",IF(AO5="-","-",IF($G5=0,0,AO5/$G5))) | AQ5: =IF($A5="","",IF($E5="","",IF(TODAY()<$E5+540,"-",IF($D5="",SUMPRODUCT(('Picked Students (raw)'!$B$2:$B$824=$C5)*('Picked Students (raw)'!$C$2:$C$824<>"")*(('Picked Students (raw)'!$C$2:$C$824-$E5)<540)),SUMPRODUCT(('Picked Students (raw)'!$B$2:$B$824=$C5)*('Picked Students (raw)'!$D$2:$D$824=$D5)*('Picked Students (raw)'!$C$2:$C$824<>"")*(('Picked Students (raw)'!$C$2:$C$824-$E5)<540)))))) | AR5: =IF($A5="","",IF(AQ5="-","-",IF($G5=0,0,AQ5/$G5))) | AS5: =IF($A5="","",IF(AQ5="-","-",$H5-AQ5))
A6: Professional Certificate Course In Data Science - July 2023 - August 2023 | B6: =IF($A6="","",IFERROR(IF(INDEX('Batch Enrollment (Metabase)'!$C$2:$C$47,MATCH($A6,'Batch Enrollment (Metabase)'!$A$2:$A$47,0))="GEM","A",IF(INDEX('Batch Enrollment (Metabase)'!$C$2:$C$47,MATCH($A6,'Batch Enrollment (Metabase)'!$A$2:$A$47,0))="Non-GEM","B","")),"")) | C6: =IF($A6="","",IFERROR(INDEX('Batch Enrollment (Metabase)'!$B$2:$B$47,MATCH($A6,'Batch Enrollment (Metabase)'!$A$2:$A$47,0)),"")) | D6: =IF($A6="","",IFERROR(INDEX('Batch Enrollment (Metabase)'!$C$2:$C$47,MATCH($A6,'Batch Enrollment (Metabase)'!$A$2:$A$47,0)),"")) | E6: =IF($A6="","",IFERROR(INDEX('Batch Enrollment (Metabase)'!$D$2:$D$47,MATCH($A6,'Batch Enrollment (Metabase)'!$A$2:$A$47,0)),"")) | F6: =IF($A6="","",IFERROR(INDEX('Batch Enrollment (Metabase)'!$E$2:$E$47,MATCH($A6,'Batch Enrollment (Metabase)'!$A$2:$A$47,0)),"")) | G6: =IF($A6="","",IFERROR(INDEX('Batch Enrollment (Metabase)'!$F$2:$F$47,MATCH($A6,'Batch Enrollment (Metabase)'!$A$2:$A$47,0)),"")) | H6: =IF($A6="","",IF($D6="",COUNTIF('Picked Students (raw)'!$B$2:$B$824,$C6),COUNTIFS('Picked Students (raw)'!$B$2:$B$824,$C6,'Picked Students (raw)'!$D$2:$D$824,$D6))) | I6: =IF($A6="","",IF($E6="","",IF(TODAY()<$E6+30,"-",IF($D6="",SUMPRODUCT(('Picked Students (raw)'!$B$2:$B$824=$C6)*('Picked Students (raw)'!$C$2:$C$824<>"")*(('Picked Students (raw)'!$C$2:$C$824-$E6)<30)),SUMPRODUCT(('Picked Students (raw)'!$B$2:$B$824=$C6)*('Picked Students (raw)'!$D$2:$D$824=$D6)*('Picked Students (raw)'!$C$2:$C$824<>"")*(('Picked Students (raw)'!$C$2:$C$824-$E6)<30)))))) | J6: =IF($A6="","",IF(I6="-","-",IF($G6=0,0,I6/$G6))) | K6: =IF($A6="","",IF($E6="","",IF(TODAY()<$E6+60,"-",IF($D6="",SUMPRODUCT(('Picked Students (raw)'!$B$2:$B$824=$C6)*('Picked Students (raw)'!$C$2:$C$824<>"")*(('Picked Students (raw)'!$C$2:$C$824-$E6)<60)),SUMPRODUCT(('Picked Students (raw)'!$B$2:$B$824=$C6)*('Picked Students (raw)'!$D$2:$D$824=$D6)*('Picked Students (raw)'!$C$2:$C$824<>"")*(('Picked Students (raw)'!$C$2:$C$824-$E6)<60)))))) | L6: =IF($A6="","",IF(K6="-","-",IF($G6=0,0,K6/$G6))) | M6: =IF($A6="","",IF($E6="","",IF(TODAY()<$E6+90,"-",IF($D6="",SUMPRODUCT(('Picked Students (raw)'!$B$2:$B$824=$C6)*('Picked Students (raw)'!$C$2:$C$824<>"")*(('Picked Students (raw)'!$C$2:$C$824-$E6)<90)),SUMPRODUCT(('Picked Students (raw)'!$B$2:$B$824=$C6)*('Picked Students (raw)'!$D$2:$D$824=$D6)*('Picked Students (raw)'!$C$2:$C$824<>"")*(('Picked Students (raw)'!$C$2:$C$824-$E6)<90)))))) | N6: =IF($A6="","",IF(M6="-","-",IF($G6=0,0,M6/$G6))) | O6: =IF($A6="","",IF($E6="","",IF(TODAY()<$E6+120,"-",IF($D6="",SUMPRODUCT(('Picked Students (raw)'!$B$2:$B$824=$C6)*('Picked Students (raw)'!$C$2:$C$824<>"")*(('Picked Students (raw)'!$C$2:$C$824-$E6)<120)),SUMPRODUCT(('Picked Students (raw)'!$B$2:$B$824=$C6)*('Picked Students (raw)'!$D$2:$D$824=$D6)*('Picked Students (raw)'!$C$2:$C$824<>"")*(('Picked Students (raw)'!$C$2:$C$824-$E6)<120)))))) | P6: =IF($A6="","",IF(O6="-","-",IF($G6=0,0,O6/$G6))) | Q6: =IF($A6="","",IF($E6="","",IF(TODAY()<$E6+150,"-",IF($D6="",SUMPRODUCT(('Picked Students (raw)'!$B$2:$B$824=$C6)*('Picked Students (raw)'!$C$2:$C$824<>"")*(('Picked Students (raw)'!$C$2:$C$824-$E6)<150)),SUMPRODUCT(('Picked Students (raw)'!$B$2:$B$824=$C6)*('Picked Students (raw)'!$D$2:$D$824=$D6)*('Picked Students (raw)'!$C$2:$C$824<>"")*(('Picked Students (raw)'!$C$2:$C$824-$E6)<150)))))) | R6: =IF($A6="","",IF(Q6="-","-",IF($G6=0,0,Q6/$G6))) | S6: =IF($A6="","",IF($E6="","",IF(TODAY()<$E6+180,"-",IF($D6="",SUMPRODUCT(('Picked Students (raw)'!$B$2:$B$824=$C6)*('Picked Students (raw)'!$C$2:$C$824<>"")*(('Picked Students (raw)'!$C$2:$C$824-$E6)<180)),SUMPRODUCT(('Picked Students (raw)'!$B$2:$B$824=$C6)*('Picked Students (raw)'!$D$2:$D$824=$D6)*('Picked Students (raw)'!$C$2:$C$824<>"")*(('Picked Students (raw)'!$C$2:$C$824-$E6)<180)))))) | T6: =IF($A6="","",IF(S6="-","-",IF($G6=0,0,S6/$G6))) | U6: =IF($A6="","",IF($E6="","",IF(TODAY()<$E6+210,"-",IF($D6="",SUMPRODUCT(('Picked Students (raw)'!$B$2:$B$824=$C6)*('Picked Students (raw)'!$C$2:$C$824<>"")*(('Picked Students (raw)'!$C$2:$C$824-$E6)<210)),SUMPRODUCT(('Picked Students (raw)'!$B$2:$B$824=$C6)*('Picked Students (raw)'!$D$2:$D$824=$D6)*('Picked Students (raw)'!$C$2:$C$824<>"")*(('Picked Students (raw)'!$C$2:$C$824-$E6)<210)))))) | V6: =IF($A6="","",IF(U6="-","-",IF($G6=0,0,U6/$G6))) | W6: =IF($A6="","",IF($E6="","",IF(TODAY()<$E6+240,"-",IF($D6="",SUMPRODUCT(('Picked Students (raw)'!$B$2:$B$824=$C6)*('Picked Students (raw)'!$C$2:$C$824<>"")*(('Picked Students (raw)'!$C$2:$C$824-$E6)<240)),SUMPRODUCT(('Picked Students (raw)'!$B$2:$B$824=$C6)*('Picked Students (raw)'!$D$2:$D$824=$D6)*('Picked Students (raw)'!$C$2:$C$824<>"")*(('Picked Students (raw)'!$C$2:$C$824-$E6)<240)))))) | X6: =IF($A6="","",IF(W6="-","-",IF($G6=0,0,W6/$G6))) | Y6: =IF($A6="","",IF($E6="","",IF(TODAY()<$E6+270,"-",IF($D6="",SUMPRODUCT(('Picked Students (raw)'!$B$2:$B$824=$C6)*('Picked Students (raw)'!$C$2:$C$824<>"")*(('Picked Students (raw)'!$C$2:$C$824-$E6)<270)),SUMPRODUCT(('Picked Students (raw)'!$B$2:$B$824=$C6)*('Picked Students (raw)'!$D$2:$D$824=$D6)*('Picked Students (raw)'!$C$2:$C$824<>"")*(('Picked Students (raw)'!$C$2:$C$824-$E6)<270)))))) | Z6: =IF($A6="","",IF(Y6="-","-",IF($G6=0,0,Y6/$G6))) | AA6: =IF($A6="","",IF($E6="","",IF(TODAY()<$E6+300,"-",IF($D6="",SUMPRODUCT(('Picked Students (raw)'!$B$2:$B$824=$C6)*('Picked Students (raw)'!$C$2:$C$824<>"")*(('Picked Students (raw)'!$C$2:$C$824-$E6)<300)),SUMPRODUCT(('Picked Students (raw)'!$B$2:$B$824=$C6)*('Picked Students (raw)'!$D$2:$D$824=$D6)*('Picked Students (raw)'!$C$2:$C$824<>"")*(('Picked Students (raw)'!$C$2:$C$824-$E6)<300)))))) | AB6: =IF($A6="","",IF(AA6="-","-",IF($G6=0,0,AA6/$G6))) | AC6: =IF($A6="","",IF($E6="","",IF(TODAY()<$E6+330,"-",IF($D6="",SUMPRODUCT(('Picked Students (raw)'!$B$2:$B$824=$C6)*('Picked Students (raw)'!$C$2:$C$824<>"")*(('Picked Students (raw)'!$C$2:$C$824-$E6)<330)),SUMPRODUCT(('Picked Students (raw)'!$B$2:$B$824=$C6)*('Picked Students (raw)'!$D$2:$D$824=$D6)*('Picked Students (raw)'!$C$2:$C$824<>"")*(('Picked Students (raw)'!$C$2:$C$824-$E6)<330)))))) | AD6: =IF($A6="","",IF(AC6="-","-",IF($G6=0,0,AC6/$G6))) | AE6: =IF($A6="","",IF($E6="","",IF(TODAY()<$E6+360,"-",IF($D6="",SUMPRODUCT(('Picked Students (raw)'!$B$2:$B$824=$C6)*('Picked Students (raw)'!$C$2:$C$824<>"")*(('Picked Students (raw)'!$C$2:$C$824-$E6)<360)),SUMPRODUCT(('Picked Students (raw)'!$B$2:$B$824=$C6)*('Picked Students (raw)'!$D$2:$D$824=$D6)*('Picked Students (raw)'!$C$2:$C$824<>"")*(('Picked Students (raw)'!$C$2:$C$824-$E6)<360)))))) | AF6: =IF($A6="","",IF(AE6="-","-",IF($G6=0,0,AE6/$G6))) | AG6: =IF($A6="","",IF($E6="","",IF(TODAY()<$E6+390,"-",IF($D6="",SUMPRODUCT(('Picked Students (raw)'!$B$2:$B$824=$C6)*('Picked Students (raw)'!$C$2:$C$824<>"")*(('Picked Students (raw)'!$C$2:$C$824-$E6)<390)),SUMPRODUCT(('Picked Students (raw)'!$B$2:$B$824=$C6)*('Picked Students (raw)'!$D$2:$D$824=$D6)*('Picked Students (raw)'!$C$2:$C$824<>"")*(('Picked Students (raw)'!$C$2:$C$824-$E6)<390)))))) | AH6: =IF($A6="","",IF(AG6="-","-",IF($G6=0,0,AG6/$G6))) | AI6: =IF($A6="","",IF($E6="","",IF(TODAY()<$E6+420,"-",IF($D6="",SUMPRODUCT(('Picked Students (raw)'!$B$2:$B$824=$C6)*('Picked Students (raw)'!$C$2:$C$824<>"")*(('Picked Students (raw)'!$C$2:$C$824-$E6)<420)),SUMPRODUCT(('Picked Students (raw)'!$B$2:$B$824=$C6)*('Picked Students (raw)'!$D$2:$D$824=$D6)*('Picked Students (raw)'!$C$2:$C$824<>"")*(('Picked Students (raw)'!$C$2:$C$824-$E6)<420)))))) | AJ6: =IF($A6="","",IF(AI6="-","-",IF($G6=0,0,AI6/$G6))) | AK6: =IF($A6="","",IF($E6="","",IF(TODAY()<$E6+450,"-",IF($D6="",SUMPRODUCT(('Picked Students (raw)'!$B$2:$B$824=$C6)*('Picked Students (raw)'!$C$2:$C$824<>"")*(('Picked Students (raw)'!$C$2:$C$824-$E6)<450)),SUMPRODUCT(('Picked Students (raw)'!$B$2:$B$824=$C6)*('Picked Students (raw)'!$D$2:$D$824=$D6)*('Picked Students (raw)'!$C$2:$C$824<>"")*(('Picked Students (raw)'!$C$2:$C$824-$E6)<450)))))) | AL6: =IF($A6="","",IF(AK6="-","-",IF($G6=0,0,AK6/$G6))) | AM6: =IF($A6="","",IF($E6="","",IF(TODAY()<$E6+480,"-",IF($D6="",SUMPRODUCT(('Picked Students (raw)'!$B$2:$B$824=$C6)*('Picked Students (raw)'!$C$2:$C$824<>"")*(('Picked Students (raw)'!$C$2:$C$824-$E6)<480)),SUMPRODUCT(('Picked Students (raw)'!$B$2:$B$824=$C6)*('Picked Students (raw)'!$D$2:$D$824=$D6)*('Picked Students (raw)'!$C$2:$C$824<>"")*(('Picked Students (raw)'!$C$2:$C$824-$E6)<480)))))) | AN6: =IF($A6="","",IF(AM6="-","-",IF($G6=0,0,AM6/$G6))) | AO6: =IF($A6="","",IF($E6="","",IF(TODAY()<$E6+510,"-",IF($D6="",SUMPRODUCT(('Picked Students (raw)'!$B$2:$B$824=$C6)*('Picked Students (raw)'!$C$2:$C$824<>"")*(('Picked Students (raw)'!$C$2:$C$824-$E6)<510)),SUMPRODUCT(('Picked Students (raw)'!$B$2:$B$824=$C6)*('Picked Students (raw)'!$D$2:$D$824=$D6)*('Picked Students (raw)'!$C$2:$C$824<>"")*(('Picked Students (raw)'!$C$2:$C$824-$E6)<510)))))) | AP6: =IF($A6="","",IF(AO6="-","-",IF($G6=0,0,AO6/$G6))) | AQ6: =IF($A6="","",IF($E6="","",IF(TODAY()<$E6+540,"-",IF($D6="",SUMPRODUCT(('Picked Students (raw)'!$B$2:$B$824=$C6)*('Picked Students (raw)'!$C$2:$C$824<>"")*(('Picked Students (raw)'!$C$2:$C$824-$E6)<540)),SUMPRODUCT(('Picked Students (raw)'!$B$2:$B$824=$C6)*('Picked Students (raw)'!$D$2:$D$824=$D6)*('Picked Students (raw)'!$C$2:$C$824<>"")*(('Picked Students (raw)'!$C$2:$C$824-$E6)<540)))))) | AR6: =IF($A6="","",IF(AQ6="-","-",IF($G6=0,0,AQ6/$G6))) | AS6: =IF($A6="","",IF(AQ6="-","-",$H6-AQ6))
